
# TestSprite AI Testing Report(MCP)

---

## 1️⃣ Document Metadata
- **Project Name:** organizational-climate-platform
- **Date:** 2025-10-08
- **Prepared by:** TestSprite AI Team

---

## 2️⃣ Requirement Validation Summary

#### Test TC001
- **Test Name:** post apiauthregister user registration
- **Test Code:** [TC001_post_apiauthregister_user_registration.py](./TC001_post_apiauthregister_user_registration.py)
- **Test Error:** Traceback (most recent call last):
  File "/var/task/handler.py", line 258, in run_with_retry
    exec(code, exec_env)
  File "<string>", line 94, in <module>
  File "<string>", line 61, in test_post_apiauthregister_user_registration
AssertionError: Expected 201, got 404 for valid user registration

- **Test Visualization and Result:** https://www.testsprite.com/dashboard/mcp/tests/f8d0cbdf-55fa-41e2-b875-d38006194387/a677a394-94a1-4cbd-9063-eea424bd3160
- **Status:** ❌ Failed
- **Analysis / Findings:** {{TODO:AI_ANALYSIS}}.
---

#### Test TC002
- **Test Name:** get apiadminusers list users with filters
- **Test Code:** [TC002_get_apiadminusers_list_users_with_filters.py](./TC002_get_apiadminusers_list_users_with_filters.py)
- **Test Error:** Traceback (most recent call last):
  File "<string>", line 23, in test_tc002_get_apiadminusers_list_users_with_filters
AssertionError: Unexpected status code 401 for pagination test

During handling of the above exception, another exception occurred:

Traceback (most recent call last):
  File "/var/task/handler.py", line 258, in run_with_retry
    exec(code, exec_env)
  File "<string>", line 113, in <module>
  File "<string>", line 28, in test_tc002_get_apiadminusers_list_users_with_filters
AssertionError: Pagination filter test failed: Unexpected status code 401 for pagination test

- **Test Visualization and Result:** https://www.testsprite.com/dashboard/mcp/tests/f8d0cbdf-55fa-41e2-b875-d38006194387/3adccedd-1401-4c75-b3e6-e9e786a3cb57
- **Status:** ❌ Failed
- **Analysis / Findings:** {{TODO:AI_ANALYSIS}}.
---

#### Test TC003
- **Test Name:** post apiadminusers create new user
- **Test Code:** [TC003_post_apiadminusers_create_new_user.py](./TC003_post_apiadminusers_create_new_user.py)
- **Test Error:** Traceback (most recent call last):
  File "<string>", line 17, in test_post_apiadminusers_create_new_user
  File "/var/task/requests/models.py", line 1024, in raise_for_status
    raise HTTPError(http_error_msg, response=self)
requests.exceptions.HTTPError: 401 Client Error: Unauthorized for url: http://localhost:3000/api/admin/departments

During handling of the above exception, another exception occurred:

Traceback (most recent call last):
  File "/var/task/handler.py", line 258, in run_with_retry
    exec(code, exec_env)
  File "<string>", line 60, in <module>
  File "<string>", line 29, in test_post_apiadminusers_create_new_user
AssertionError: Failed to fetch departments: 401 Client Error: Unauthorized for url: http://localhost:3000/api/admin/departments

- **Test Visualization and Result:** https://www.testsprite.com/dashboard/mcp/tests/f8d0cbdf-55fa-41e2-b875-d38006194387/9b24ab66-9ef1-4bfc-8f81-c39bc8561c71
- **Status:** ❌ Failed
- **Analysis / Findings:** {{TODO:AI_ANALYSIS}}.
---

#### Test TC004
- **Test Name:** put apiadminusersid update user by id
- **Test Code:** [TC004_put_apiadminusersid_update_user_by_id.py](./TC004_put_apiadminusersid_update_user_by_id.py)
- **Test Error:** Traceback (most recent call last):
  File "/var/task/handler.py", line 258, in run_with_retry
    exec(code, exec_env)
  File "<string>", line 55, in <module>
  File "<string>", line 24, in test_put_apiadminusersid_update_user_by_id
AssertionError: User creation failed: {"error":"Unauthorized"}

- **Test Visualization and Result:** https://www.testsprite.com/dashboard/mcp/tests/f8d0cbdf-55fa-41e2-b875-d38006194387/4f923365-d77d-417f-94d6-bda5f869595c
- **Status:** ❌ Failed
- **Analysis / Findings:** {{TODO:AI_ANALYSIS}}.
---

#### Test TC005
- **Test Name:** delete apiadminusersid delete user by id
- **Test Code:** [TC005_delete_apiadminusersid_delete_user_by_id.py](./TC005_delete_apiadminusersid_delete_user_by_id.py)
- **Test Error:** Traceback (most recent call last):
  File "/var/task/handler.py", line 258, in run_with_retry
    exec(code, exec_env)
  File "<string>", line 67, in <module>
  File "<string>", line 27, in test_delete_apiadminusersid_delete_user_by_id
AssertionError: User creation failed: {"error":"Unauthorized"}

- **Test Visualization and Result:** https://www.testsprite.com/dashboard/mcp/tests/f8d0cbdf-55fa-41e2-b875-d38006194387/c5efd463-4e9b-4876-8566-4bb670a6cfa5
- **Status:** ❌ Failed
- **Analysis / Findings:** {{TODO:AI_ANALYSIS}}.
---

#### Test TC006
- **Test Name:** get apiadmincompanies list all companies
- **Test Code:** [TC006_get_apiadmincompanies_list_all_companies.py](./TC006_get_apiadmincompanies_list_all_companies.py)
- **Test Error:** Traceback (most recent call last):
  File "<string>", line 16, in test_get_apiadmincompanies_list_all_companies
  File "/var/task/requests/models.py", line 1024, in raise_for_status
    raise HTTPError(http_error_msg, response=self)
requests.exceptions.HTTPError: 401 Client Error: Unauthorized for url: http://localhost:3000/api/admin/companies

During handling of the above exception, another exception occurred:

Traceback (most recent call last):
  File "/var/task/handler.py", line 258, in run_with_retry
    exec(code, exec_env)
  File "<string>", line 31, in <module>
  File "<string>", line 29, in test_get_apiadmincompanies_list_all_companies
AssertionError: Request failed: 401 Client Error: Unauthorized for url: http://localhost:3000/api/admin/companies

- **Test Visualization and Result:** https://www.testsprite.com/dashboard/mcp/tests/f8d0cbdf-55fa-41e2-b875-d38006194387/93133655-02c8-4abd-b0ed-4f1518e0a4d1
- **Status:** ❌ Failed
- **Analysis / Findings:** {{TODO:AI_ANALYSIS}}.
---

#### Test TC007
- **Test Name:** post apiadmincompanies create new company
- **Test Code:** [TC007_post_apiadmincompanies_create_new_company.py](./TC007_post_apiadmincompanies_create_new_company.py)
- **Test Error:** Traceback (most recent call last):
  File "/var/task/handler.py", line 258, in run_with_retry
    exec(code, exec_env)
  File "<string>", line 48, in <module>
  File "<string>", line 28, in test_post_apiadmincompanies_create_new_company
AssertionError: Expected 201 Created, got 401

- **Test Visualization and Result:** https://www.testsprite.com/dashboard/mcp/tests/f8d0cbdf-55fa-41e2-b875-d38006194387/81444b1c-2c4e-48a0-a445-8c8cf33d51ee
- **Status:** ❌ Failed
- **Analysis / Findings:** {{TODO:AI_ANALYSIS}}.
---

#### Test TC008
- **Test Name:** get apiadmindepartments list all departments
- **Test Code:** [TC008_get_apiadmindepartments_list_all_departments.py](./TC008_get_apiadmindepartments_list_all_departments.py)
- **Test Error:** Traceback (most recent call last):
  File "<string>", line 10, in test_get_apiadmindepartments_list_all_departments
  File "/var/task/requests/models.py", line 1024, in raise_for_status
    raise HTTPError(http_error_msg, response=self)
requests.exceptions.HTTPError: 401 Client Error: Unauthorized for url: http://localhost:3000/api/admin/departments

During handling of the above exception, another exception occurred:

Traceback (most recent call last):
  File "/var/task/handler.py", line 258, in run_with_retry
    exec(code, exec_env)
  File "<string>", line 19, in <module>
  File "<string>", line 17, in test_get_apiadmindepartments_list_all_departments
AssertionError: HTTP request failed: 401 Client Error: Unauthorized for url: http://localhost:3000/api/admin/departments

- **Test Visualization and Result:** https://www.testsprite.com/dashboard/mcp/tests/f8d0cbdf-55fa-41e2-b875-d38006194387/f0f92c06-dd77-4e63-b1ca-2f96a872c745
- **Status:** ❌ Failed
- **Analysis / Findings:** {{TODO:AI_ANALYSIS}}.
---

#### Test TC009
- **Test Name:** post apiadmindepartments create new department
- **Test Code:** [TC009_post_apiadmindepartments_create_new_department.py](./TC009_post_apiadmindepartments_create_new_department.py)
- **Test Error:** Traceback (most recent call last):
  File "/var/task/handler.py", line 258, in run_with_retry
    exec(code, exec_env)
  File "<string>", line 57, in <module>
  File "<string>", line 21, in test_post_apiadmindepartments_create_new_department
AssertionError: Failed to create company: {"success":false,"data":null,"error":"Authentication required"}

- **Test Visualization and Result:** https://www.testsprite.com/dashboard/mcp/tests/f8d0cbdf-55fa-41e2-b875-d38006194387/e327202b-63ca-488a-a2f0-18ef18bfe4ec
- **Status:** ❌ Failed
- **Analysis / Findings:** {{TODO:AI_ANALYSIS}}.
---

#### Test TC010
- **Test Name:** get apidashboardcompanyadmin get company admin dashboard data
- **Test Code:** [TC010_get_apidashboardcompanyadmin_get_company_admin_dashboard_data.py](./TC010_get_apidashboardcompanyadmin_get_company_admin_dashboard_data.py)
- **Test Error:** Traceback (most recent call last):
  File "/var/task/handler.py", line 258, in run_with_retry
    exec(code, exec_env)
  File "<string>", line 33, in <module>
  File "<string>", line 13, in test_get_company_admin_dashboard_data
AssertionError: Expected status code 200, got 403

- **Test Visualization and Result:** https://www.testsprite.com/dashboard/mcp/tests/f8d0cbdf-55fa-41e2-b875-d38006194387/4ee64680-3dfc-454d-be62-fc83dfca97fd
- **Status:** ❌ Failed
- **Analysis / Findings:** {{TODO:AI_ANALYSIS}}.
---


## 3️⃣ Coverage & Matching Metrics

- **0.00** of tests passed

| Requirement        | Total Tests | ✅ Passed | ❌ Failed  |
|--------------------|-------------|-----------|------------|
| ...                | ...         | ...       | ...        |
---


## 4️⃣ Key Gaps / Risks
{AI_GNERATED_KET_GAPS_AND_RISKS}
---